Workbook

Sheet Total Monthly
A1: Month | B1: Start | C1: Open Long Stocks | D1: Open Short | E1: Fund Change | F1: Total Unrealized | G1: Total Realized | H1: Unrealized Long | I1: Realized long | J1: Dividends | K1: Total Long | L1: Long Monthly | M1: Long (cumulative) | N1: Unrealized Short | O1: Realized Short | P1: Total Short | Q1: Short Monthly | R1: Short (cumulative) | S1: Total | T1: Portfolio Performance | U1: Portfolio (cumulative) | V1: SPY monthly | W1: SPY (cumulative) | X1: Excess Retune
A2: 0 | T2: 0 | U2: 0 | V2: 0 | W2: 0 | X2: =T2-V2 -> 0
A3: 2024-01 | B3: 250000 | C3: =SUMIFS('Portfolio Raw Data'!M:M,'Portfolio Raw Data'!A:A,A3,'Portfolio Raw Data'!B:B,"Open Positions",'Portfolio Raw Data'!C:C,"Total",'Portfolio Raw Data'!E:E,"Stocks") -> 186063.87 | D3: =SUMIFS('Portfolio Raw Data'!M:M,'Portfolio Raw Data'!A:A,A3,'Portfolio Raw Data'!B:B,"Open Positions",'Portfolio Raw Data'!C:C,"Total",'Portfolio Raw Data'!E:E,"Futures") -> -194820 | F3: =SUMIFS('Portfolio Raw Data'!P:P,'Portfolio Raw Data'!A:A,A3,'Portfolio Raw Data'!B:B,"Realized & Unrealized Performance Summary",'Portfolio Raw Data'!C:C,"Data",'Portfolio Raw Data'!D:D,"Total (All Assets)") -> 5851.933 | G3: =SUMIFS('Portfolio Raw Data'!K:K,'Portfolio Raw Data'!A:A,A3,'Portfolio Raw Data'!B:B,"Realized & Unrealized Performance Summary",'Portfolio Raw Data'!C:C,"Data",'Portfolio Raw Data'!D:D,"Total (All Assets)") -> -1011.16 | H3: =SUMIFS('Portfolio Raw Data'!P:P,'Portfolio Raw Data'!A:A,A3,'Portfolio Raw Data'!B:B,"Realized & Unrealized Performance Summary",'Portfolio Raw Data'!C:C,"Data",'Portfolio Raw Data'!D:D,"Total")+-1*SUMIFS('Portfolio Raw Data'!P:P,'Portfolio Raw Data'!A:A,A3,'Portfolio Raw Data'!B:B,"Realized & Unrealized Performance Summary",'Portfolio Raw Data'!C:C,"Data",'Portfolio Raw Data'!D:D,"Futures") -> 10439.683 | I3: =SUMIFS('Portfolio Raw Data'!K:K,'Portfolio Raw Data'!A:A,A3,'Portfolio Raw Data'!B:B,"Realized & Unrealized Performance Summary",'Portfolio Raw Data'!C:C,"Data",'Portfolio Raw Data'!D:D,"Total")+-1*SUMIFS('Portfolio Raw Data'!K:K,'Portfolio Raw Data'!A:A,A3,'Portfolio Raw Data'!B:B,"Realized & Unrealized Performance Summary",'Portfolio Raw Data'!C:C,"Data",'Portfolio Raw Data'!D:D,"Futures") -> -1011.16 | J3: =SUMIFS('Portfolio Raw Data'!O:O,'Portfolio Raw Data'!A:A,A3,'Portfolio Raw Data'!B:B,"Change in Dividend Accruals",'Portfolio Raw Data'!C:C,"Data",'Portfolio Raw Data'!D:D,"Ending Dividend Accruals in USD") -> 57.17 | K3: =I3+H3+J3 -> 9485.693 | L3: =K3/B3 -> 0.037942772 | M3: {=PRODUCT(1+L$3:L3)-1} -> 0.037942772 | N3: =SUMIFS('Portfolio Raw Data'!P:P,'Portfolio Raw Data'!A:A,A3,'Portfolio Raw Data'!B:B,"Realized & Unrealized Performance Summary",'Portfolio Raw Data'!C:C,"Data",'Portfolio Raw Data'!D:D,"Futures") -> -4587.75 | O3: =SUMIFS('Portfolio Raw Data'!K:K,'Portfolio Raw Data'!A:A,A3,'Portfolio Raw Data'!B:B,"Realized & Unrealized Performance Summary",'Portfolio Raw Data'!C:C,"Data",'Portfolio Raw Data'!D:D,"Futures") -> 0 | P3: =O3+N3 -> -4587.75 | Q3: =P3/B3 -> -0.018351 | R3: {=PRODUCT(1+Q$3:Q3)-1} -> -0.018351 | S3: =P3+K3 -> 4897.943 | T3: =(B3+S3)/B3-1 -> 0.019591772 | U3: {=PRODUCT(1+T$3:T3)-1} -> 0.019591772 | V3: =VLOOKUP(A3,'SPY Raw Data'!A:E,5,0)/100 -> 0.01592647 | W3: {=PRODUCT(1+V$2:V3)-1} -> 0.01592647 | X3: =T3-V3 -> 0.0036653022 | Z3: Portfolio Properties
A4: 2024-02 | B4: =B3+S3 -> 254897.94 | C4: =SUMIFS('Portfolio Raw Data'!M:M,'Portfolio Raw Data'!A:A,A4,'Portfolio Raw Data'!B:B,"Open Positions",'Portfolio Raw Data'!C:C,"Total",'Portfolio Raw Data'!E:E,"Stocks") -> 209001.39 | D4: =SUMIFS('Portfolio Raw Data'!M:M,'Portfolio Raw Data'!A:A,A4,'Portfolio Raw Data'!B:B,"Open Positions",'Portfolio Raw Data'!C:C,"Total",'Portfolio Raw Data'!E:E,"Futures") -> -204150 | F4: =SUMIFS('Portfolio Raw Data'!P:P,'Portfolio Raw Data'!A:A,A4,'Portfolio Raw Data'!B:B,"Realized & Unrealized Performance Summary",'Portfolio Raw Data'!C:C,"Data",'Portfolio Raw Data'!D:D,"Total (All Assets)") -> 2745.5189 | G4: =SUMIFS('Portfolio Raw Data'!K:K,'Portfolio Raw Data'!A:A,A4,'Portfolio Raw Data'!B:B,"Realized & Unrealized Performance Summary",'Portfolio Raw Data'!C:C,"Data",'Portfolio Raw Data'!D:D,"Total (All Assets)") -> 6027.4241 | H4: =SUMIFS('Portfolio Raw Data'!P:P,'Portfolio Raw Data'!A:A,A4,'Portfolio Raw Data'!B:B,"Realized & Unrealized Performance Summary",'Portfolio Raw Data'!C:C,"Data",'Portfolio Raw Data'!D:D,"Total")+-1*SUMIFS('Portfolio Raw Data'!P:P,'Portfolio Raw Data'!A:A,A4,'Portfolio Raw Data'!B:B,"Realized & Unrealized Performance Summary",'Portfolio Raw Data'!C:C,"Data",'Portfolio Raw Data'!D:D,"Futures") -> 14932.019 | I4: =SUMIFS('Portfolio Raw Data'!K:K,'Portfolio Raw Data'!A:A,A4,'Portfolio Raw Data'!B:B,"Realized & Unrealized Performance Summary",'Portfolio Raw Data'!C:C,"Data",'Portfolio Raw Data'!D:D,"Total")+-1*SUMIFS('Portfolio Raw Data'!K:K,'Portfolio Raw Data'!A:A,A4,'Portfolio Raw Data'!B:B,"Realized & Unrealized Performance Summary",'Portfolio Raw Data'!C:C,"Data",'Portfolio Raw Data'!D:D,"Futures") -> 7312.1741 | J4: =SUMIFS('Portfolio Raw Data'!O:O,'Portfolio Raw Data'!A:A,A4,'Portfolio Raw Data'!B:B,"Change in Dividend Accruals",'Portfolio Raw Data'!C:C,"Data",'Portfolio Raw Data'!D:D,"Ending Dividend Accruals in USD") -> 177.5 | K4: =I4+H4+J4 -> 22421.693 | L4: =K4/B4 -> 0.087963413 | M4: {=PRODUCT(1+L$3:L4)-1} -> 0.12924376 | N4: =SUMIFS('Portfolio Raw Data'!P:P,'Portfolio Raw Data'!A:A,A4,'Portfolio Raw Data'!B:B,"Realized & Unrealized Performance Summary",'Portfolio Raw Data'!C:C,"Data",'Portfolio Raw Data'!D:D,"Futures") -> -12186.5 | O4: =SUMIFS('Portfolio Raw Data'!K:K,'Portfolio Raw Data'!A:A,A4,'Portfolio Raw Data'!B:B,"Realized & Unrealized Performance Summary",'Portfolio Raw Data'!C:C,"Data",'Portfolio Raw Data'!D:D,"Futures") -> -1284.75 | P4: =O4+N4 -> -13471.25 | Q4: =P4/B4 -> -0.052849583 | R4: {=PRODUCT(1+Q$3:Q4)-1} -> -0.07023074 | S4: =P4+K4 -> 8950.443 | T4: =(B4+S4)/B4-1 -> 0.03511383 | U4: {=PRODUCT(1+T$3:T4)-1} -> 0.055393544 | V4: =VLOOKUP(A4,'SPY Raw Data'!A:E,5,0)/100 -> 0.052186856 | W4: {=PRODUCT(1+V$2:V4)-1} -> 0.068944478 | X4: =T4-V4 -> -0.017073026 | Z4: Construction | AA4: Equal weights
A5: 2024-03 | B5: =B4+S4 -> 263848.39 | C5: =SUMIFS('Portfolio Raw Data'!M:M,'Portfolio Raw Data'!A:A,A5,'Portfolio Raw Data'!B:B,"Open Positions",'Portfolio Raw Data'!C:C,"Total",'Portfolio Raw Data'!E:E,"Stocks") -> 250391.92 | D5: =SUMIFS('Portfolio Raw Data'!M:M,'Portfolio Raw Data'!A:A,A5,'Portfolio Raw Data'!B:B,"Open Positions",'Portfolio Raw Data'!C:C,"Total",'Portfolio Raw Data'!E:E,"Futures") -> -249290 | F5: =SUMIFS('Portfolio Raw Data'!P:P,'Portfolio Raw Data'!A:A,A5,'Portfolio Raw Data'!B:B,"Realized & Unrealized Performance Summary",'Portfolio Raw Data'!C:C,"Data",'Portfolio Raw Data'!D:D,"Total (All Assets)") -> 12798.79 | G5: =SUMIFS('Portfolio Raw Data'!K:K,'Portfolio Raw Data'!A:A,A5,'Portfolio Raw Data'!B:B,"Realized & Unrealized Performance Summary",'Portfolio Raw Data'!C:C,"Data",'Portfolio Raw Data'!D:D,"Total (All Assets)") -> -8795.3708 | H5: =SUMIFS('Portfolio Raw Data'!P:P,'Portfolio Raw Data'!A:A,A5,'Portfolio Raw Data'!B:B,"Realized & Unrealized Performance Summary",'Portfolio Raw Data'!C:C,"Data",'Portfolio Raw Data'!D:D,"Total")+-1*SUMIFS('Portfolio Raw Data'!P:P,'Portfolio Raw Data'!A:A,A5,'Portfolio Raw Data'!B:B,"Realized & Unrealized Performance Summary",'Portfolio Raw Data'!C:C,"Data",'Portfolio Raw Data'!D:D,"Futures") -> 18764.29 | I5: =SUMIFS('Portfolio Raw Data'!K:K,'Portfolio Raw Data'!A:A,A5,'Portfolio Raw Data'!B:B,"Realized & Unrealized Performance Summary",'Portfolio Raw Data'!C:C,"Data",'Portfolio Raw Data'!D:D,"Total")+-1*SUMIFS('Portfolio Raw Data'!K:K,'Portfolio Raw Data'!A:A,A5,'Portfolio Raw Data'!B:B,"Realized & Unrealized Performance Summary",'Portfolio Raw Data'!C:C,"Data",'Portfolio Raw Data'!D:D,"Futures") -> 3303.8792 | J5: =SUMIFS('Portfolio Raw Data'!O:O,'Portfolio Raw Data'!A:A,A5,'Portfolio Raw Data'!B:B,"Change in Dividend Accruals",'Portfolio Raw Data'!C:C,"Data",'Portfolio Raw Data'!D:D,"Ending Dividend Accruals in USD") -> 86.99 | K5: =I5+H5+J5 -> 22155.159 | L5: =K5/B5 -> 0.083969279 | M5: {=PRODUCT(1+L$3:L5)-1} -> 0.22406555 | N5: =SUMIFS('Portfolio Raw Data'!P:P,'Portfolio Raw Data'!A:A,A5,'Portfolio Raw Data'!B:B,"Realized & Unrealized Performance Summary",'Portfolio Raw Data'!C:C,"Data",'Portfolio Raw Data'!D:D,"Futures") -> -5965.5 | O5: =SUMIFS('Portfolio Raw Data'!K:K,'Portfolio Raw Data'!A:A,A5,'Portfolio Raw Data'!B:B,"Realized & Unrealized Performance Summary",'Portfolio Raw Data'!C:C,"Data",'Portfolio Raw Data'!D:D,"Futures") -> -12099.25 | P5: =O5+N5 -> -18064.75 | Q5: =P5/B5 -> -0.068466403 | R5: {=PRODUCT(1+Q$3:Q5)-1} -> -0.1338887 | S5: =P5+K5 -> 4090.4089 | T5: =(B5+S5)/B5-1 -> 0.015502876 | U5: {=PRODUCT(1+T$3:T5)-1} -> 0.071755179 | V5: =VLOOKUP(A5,'SPY Raw Data'!A:E,5,0)/100 -> 0.032701738 | W5: {=PRODUCT(1+V$2:V5)-1} -> 0.10390082 | X5: =T5-V5 -> -0.017198862 | Z5: Avg Number of Positions | AA5: 30
A6: 2024-04 | B6: =B5+S5 -> 267938.79 | C6: =SUMIFS('Portfolio Raw Data'!M:M,'Portfolio Raw Data'!A:A,A6,'Portfolio Raw Data'!B:B,"Open Positions",'Portfolio Raw Data'!C:C,"Total",'Portfolio Raw Data'!E:E,"Stocks") -> 220153.73 | D6: =SUMIFS('Portfolio Raw Data'!M:M,'Portfolio Raw Data'!A:A,A6,'Portfolio Raw Data'!B:B,"Open Positions",'Portfolio Raw Data'!C:C,"Total",'Portfolio Raw Data'!E:E,"Futures") -> -212487.5 | F6: =SUMIFS('Portfolio Raw Data'!P:P,'Portfolio Raw Data'!A:A,A6,'Portfolio Raw Data'!B:B,"Realized & Unrealized Performance Summary",'Portfolio Raw Data'!C:C,"Data",'Portfolio Raw Data'!D:D,"Total (All Assets)") -> 8713.2895 | G6: =SUMIFS('Portfolio Raw Data'!K:K,'Portfolio Raw Data'!A:A,A6,'Portfolio Raw Data'!B:B,"Realized & Unrealized Performance Summary",'Portfolio Raw Data'!C:C,"Data",'Portfolio Raw Data'!D:D,"Total (All Assets)") -> 5338.7158 | H6: =SUMIFS('Portfolio Raw Data'!P:P,'Portfolio Raw Data'!A:A,A6,'Portfolio Raw Data'!B:B,"Realized & Unrealized Performance Summary",'Portfolio Raw Data'!C:C,"Data",'Portfolio Raw Data'!D:D,"Total")+-1*SUMIFS('Portfolio Raw Data'!P:P,'Portfolio Raw Data'!A:A,A6,'Portfolio Raw Data'!B:B,"Realized & Unrealized Performance Summary",'Portfolio Raw Data'!C:C,"Data",'Portfolio Raw Data'!D:D,"Futures") -> 3913.2895 | I6: =SUMIFS('Portfolio Raw Data'!K:K,'Portfolio Raw Data'!A:A,A6,'Portfolio Raw Data'!B:B,"Realized & Unrealized Performance Summary",'Portfolio Raw Data'!C:C,"Data",'Portfolio Raw Data'!D:D,"Total")+-1*SUMIFS('Portfolio Raw Data'!K:K,'Portfolio Raw Data'!A:A,A6,'Portfolio Raw Data'!B:B,"Realized & Unrealized Performance Summary",'Portfolio Raw Data'!C:C,"Data",'Portfolio Raw Data'!D:D,"Futures") -> 4924.7158 | J6: =SUMIFS('Portfolio Raw Data'!O:O,'Portfolio Raw Data'!A:A,A6,'Portfolio Raw Data'!B:B,"Change in Dividend Accruals",'Portfolio Raw Data'!C:C,"Data",'Portfolio Raw Data'!D:D,"Ending Dividend Accruals in USD") -> 41.6 | K6: =I6+H6+J6 -> 8879.6053 | L6: =K6/B6 -> 0.033140424 | M6: {=PRODUCT(1+L$3:L6)-1} -> 0.2646316 | N6: =SUMIFS('Portfolio Raw Data'!P:P,'Portfolio Raw Data'!A:A,A6,'Portfolio Raw Data'!B:B,"Realized & Unrealized Performance Summary",'Portfolio Raw Data'!C:C,"Data",'Portfolio Raw Data'!D:D,"Futures") -> 4800 | O6: =SUMIFS('Portfolio Raw Data'!K:K,'Portfolio Raw Data'!A:A,A6,'Portfolio Raw Data'!B:B,"Realized & Unrealized Performance Summary",'Portfolio Raw Data'!C:C,"Data",'Portfolio Raw Data'!D:D,"Futures") -> 414 | P6: =O6+N6 -> 5214 | Q6: =P6/B6 -> 0.019459668 | R6: {=PRODUCT(1+Q$3:Q6)-1} -> -0.11703446 | S6: =P6+K6 -> 14093.605 | T6: =(B6+S6)/B6-1 -> 0.052600092 | U6: {=PRODUCT(1+T$3:T6)-1} -> 0.1281296 | V6: =VLOOKUP(A6,'SPY Raw Data'!A:E,5,0)/100 -> -0.040319627 | W6: {=PRODUCT(1+V$2:V6)-1} -> 0.059391951 | X6: =T6-V6 -> 0.092919719 | Z6: Sector allocation | AA6: Sentiment
A7: 2024-05 | B7: =B6+S6 -> 282032.4 | C7: =SUMIFS('Portfolio Raw Data'!M:M,'Portfolio Raw Data'!A:A,A7,'Portfolio Raw Data'!B:B,"Open Positions",'Portfolio Raw Data'!C:C,"Total",'Portfolio Raw Data'!E:E,"Stocks") -> 452742.7 | D7: =SUMIFS('Portfolio Raw Data'!M:M,'Portfolio Raw Data'!A:A,A7,'Portfolio Raw Data'!B:B,"Open Positions",'Portfolio Raw Data'!C:C,"Total",'Portfolio Raw Data'!E:E,"Futures") -> -429276 | E7: =SUMIFS('Portfolio Raw Data'!E:E,'Portfolio Raw Data'!A:A,A3,'Portfolio Raw Data'!B:B,"Net Asset Value",'Portfolio Raw Data'!C:C,"Data",'Portfolio Raw Data'!D:D,"Cash ") -> 250000 | F7: =SUMIFS('Portfolio Raw Data'!P:P,'Portfolio Raw Data'!A:A,A7,'Portfolio Raw Data'!B:B,"Realized & Unrealized Performance Summary",'Portfolio Raw Data'!C:C,"Data",'Portfolio Raw Data'!D:D,"Total (All Assets)") -> 10451.155 | G7: =SUMIFS('Portfolio Raw Data'!K:K,'Portfolio Raw Data'!A:A,A7,'Portfolio Raw Data'!B:B,"Realized & Unrealized Performance Summary",'Portfolio Raw Data'!C:C,"Data",'Portfolio Raw Data'!D:D,"Total (All Assets)") -> -245.46341 | H7: =SUMIFS('Portfolio Raw Data'!P:P,'Portfolio Raw Data'!A:A,A7,'Portfolio Raw Data'!B:B,"Realized & Unrealized Performance Summary",'Portfolio Raw Data'!C:C,"Data",'Portfolio Raw Data'!D:D,"Total")+-1*SUMIFS('Portfolio Raw Data'!P:P,'Portfolio Raw Data'!A:A,A7,'Portfolio Raw Data'!B:B,"Realized & Unrealized Performance Summary",'Portfolio Raw Data'!C:C,"Data",'Portfolio Raw Data'!D:D,"Futures") -> 17864.405 | I7: =SUMIFS('Portfolio Raw Data'!K:K,'Portfolio Raw Data'!A:A,A7,'Portfolio Raw Data'!B:B,"Realized & Unrealized Performance Summary",'Portfolio Raw Data'!C:C,"Data",'Portfolio Raw Data'!D:D,"Total")+-1*SUMIFS('Portfolio Raw Data'!K:K,'Portfolio Raw Data'!A:A,A7,'Portfolio Raw Data'!B:B,"Realized & Unrealized Performance Summary",'Portfolio Raw Data'!C:C,"Data",'Portfolio Raw Data'!D:D,"Futures") -> 641.78659 | J7: =SUMIFS('Portfolio Raw Data'!O:O,'Portfolio Raw Data'!A:A,A7,'Portfolio Raw Data'!B:B,"Change in Dividend Accruals",'Portfolio Raw Data'!C:C,"Data",'Portfolio Raw Data'!D:D,"Ending Dividend Accruals in USD") -> 210.06 | K7: =I7+H7+J7 -> 18716.252 | L7: =K7/B7 -> 0.066362063 | M7: {=PRODUCT(1+L$3:L7)-1} -> 0.34855516 | N7: =SUMIFS('Portfolio Raw Data'!P:P,'Portfolio Raw Data'!A:A,A7,'Portfolio Raw Data'!B:B,"Realized & Unrealized Performance Summary",'Portfolio Raw Data'!C:C,"Data",'Portfolio Raw Data'!D:D,"Futures") -> -7413.25 | O7: =SUMIFS('Portfolio Raw Data'!K:K,'Portfolio Raw Data'!A:A,A7,'Portfolio Raw Data'!B:B,"Realized & Unrealized Performance Summary",'Portfolio Raw Data'!C:C,"Data",'Portfolio Raw Data'!D:D,"Futures") -> -887.25 | P7: =O7+N7 -> -8300.5 | Q7: =P7/B7 -> -0.029431016 | R7: {=PRODUCT(1+Q$3:Q7)-1} -> -0.14302103 | S7: =P7+K7 -> 10415.752 | T7: =(B7+S7)/B7-1 -> 0.036931048 | U7: {=PRODUCT(1+T$3:T7)-1} -> 0.16979261 | V7: =VLOOKUP(A7,'SPY Raw Data'!A:E,5,0)/100 -> 0.05057974 | W7: {=PRODUCT(1+V$2:V7)-1} -> 0.11297572 | X7: =T7-V7 -> -0.013648692 | Z7: Hedging | AA7: Yes
A8: 2024-06 | B8: =B7+S7+E7 -> 542448.15 | C8: =SUMIFS('Portfolio Raw Data'!M:M,'Portfolio Raw Data'!A:A,A8,'Portfolio Raw Data'!B:B,"Open Positions",'Portfolio Raw Data'!C:C,"Total",'Portfolio Raw Data'!E:E,"Stocks") -> 465468.75 | D8: =SUMIFS('Portfolio Raw Data'!M:M,'Portfolio Raw Data'!A:A,A8,'Portfolio Raw Data'!B:B,"Open Positions",'Portfolio Raw Data'!C:C,"Total",'Portfolio Raw Data'!E:E,"Futures") -> -438606.5 | F8: =SUMIFS('Portfolio Raw Data'!P:P,'Portfolio Raw Data'!A:A,A8,'Portfolio Raw Data'!B:B,"Realized & Unrealized Performance Summary",'Portfolio Raw Data'!C:C,"Data",'Portfolio Raw Data'!D:D,"Total (All Assets)") -> 31489.245 | G8: =SUMIFS('Portfolio Raw Data'!K:K,'Portfolio Raw Data'!A:A,A8,'Portfolio Raw Data'!B:B,"Realized & Unrealized Performance Summary",'Portfolio Raw Data'!C:C,"Data",'Portfolio Raw Data'!D:D,"Total (All Assets)") -> -20966.079 | H8: =SUMIFS('Portfolio Raw Data'!P:P,'Portfolio Raw Data'!A:A,A8,'Portfolio Raw Data'!B:B,"Realized & Unrealized Performance Summary",'Portfolio Raw Data'!C:C,"Data",'Portfolio Raw Data'!D:D,"Total")+-1*SUMIFS('Portfolio Raw Data'!P:P,'Portfolio Raw Data'!A:A,A8,'Portfolio Raw Data'!B:B,"Realized & Unrealized Performance Summary",'Portfolio Raw Data'!C:C,"Data",'Portfolio Raw Data'!D:D,"Futures") -> 27627.245 | I8: =SUMIFS('Portfolio Raw Data'!K:K,'Portfolio Raw Data'!A:A,A8,'Portfolio Raw Data'!B:B,"Realized & Unrealized Performance Summary",'Portfolio Raw Data'!C:C,"Data",'Portfolio Raw Data'!D:D,"Total")+-1*SUMIFS('Portfolio Raw Data'!K:K,'Portfolio Raw Data'!A:A,A8,'Portfolio Raw Data'!B:B,"Realized & Unrealized Performance Summary",'Portfolio Raw Data'!C:C,"Data",'Portfolio Raw Data'!D:D,"Futures") -> 6907.9208 | J8: =SUMIFS('Portfolio Raw Data'!O:O,'Portfolio Raw Data'!A:A,A8,'Portfolio Raw Data'!B:B,"Change in Dividend Accruals",'Portfolio Raw Data'!C:C,"Data",'Portfolio Raw Data'!D:D,"Ending Dividend Accruals in USD") -> 71.45 | K8: =I8+H8+J8 -> 34606.615 | L8: =K8/B8 -> 0.063797093 | M8: {=PRODUCT(1+L$3:L8)-1} -> 0.43458906 | N8: =SUMIFS('Portfolio Raw Data'!P:P,'Portfolio Raw Data'!A:A,A8,'Portfolio Raw Data'!B:B,"Realized & Unrealized Performance Summary",'Portfolio Raw Data'!C:C,"Data",'Portfolio Raw Data'!D:D,"Futures") -> 3862 | O8: =SUMIFS('Portfolio Raw Data'!K:K,'Portfolio Raw Data'!A:A,A8,'Portfolio Raw Data'!B:B,"Realized & Unrealized Performance Summary",'Portfolio Raw Data'!C:C,"Data",'Portfolio Raw Data'!D:D,"Futures") -> -27874 | P8: =O8+N8 -> -24012 | Q8: =P8/B8 -> -0.044265982 | R8: {=PRODUCT(1+Q$3:Q8)-1} -> -0.18095605 | S8: =P8+K8 -> 10594.615 | T8: =(B8+S8)/B8-1 -> 0.019531112 | U8: {=PRODUCT(1+T$3:T8)-1} -> 0.19263996 | V8: =VLOOKUP(A8,'SPY Raw Data'!A:E,5,0)/100 -> 0.035280215 | W8: {=PRODUCT(1+V$2:V8)-1} -> 0.15224174 | X8: =T8-V8 -> -0.015749103 | Z8: Benchmark | AA8: SPY
A9: 2024-07 | B9: =B8+S8 -> 553042.77 | C9: =SUMIFS('Portfolio Raw Data'!M:M,'Portfolio Raw Data'!A:A,A9,'Portfolio Raw Data'!B:B,"Open Positions",'Portfolio Raw Data'!C:C,"Total",'Portfolio Raw Data'!E:E,"Stocks") -> 454643.32 | D9: =SUMIFS('Portfolio Raw Data'!M:M,'Portfolio Raw Data'!A:A,A9,'Portfolio Raw Data'!B:B,"Open Positions",'Portfolio Raw Data'!C:C,"Total",'Portfolio Raw Data'!E:E,"Futures") -> -428593 | F9: =SUMIFS('Portfolio Raw Data'!P:P,'Portfolio Raw Data'!A:A,A9,'Portfolio Raw Data'!B:B,"Realized & Unrealized Performance Summary",'Portfolio Raw Data'!C:C,"Data",'Portfolio Raw Data'!D:D,"Total (All Assets)") -> 13140.742 | G9: =SUMIFS('Portfolio Raw Data'!K:K,'Portfolio Raw Data'!A:A,A9,'Portfolio Raw Data'!B:B,"Realized & Unrealized Performance Summary",'Portfolio Raw Data'!C:C,"Data",'Portfolio Raw Data'!D:D,"Total (All Assets)") -> 7623.4324 | H9: =SUMIFS('Portfolio Raw Data'!P:P,'Portfolio Raw Data'!A:A,A9,'Portfolio Raw Data'!B:B,"Realized & Unrealized Performance Summary",'Portfolio Raw Data'!C:C,"Data",'Portfolio Raw Data'!D:D,"Total")+-1*SUMIFS('Portfolio Raw Data'!P:P,'Portfolio Raw Data'!A:A,A9,'Portfolio Raw Data'!B:B,"Realized & Unrealized Performance Summary",'Portfolio Raw Data'!C:C,"Data",'Portfolio Raw Data'!D:D,"Futures") -> 15571.742 | I9: =SUMIFS('Portfolio Raw Data'!K:K,'Portfolio Raw Data'!A:A,A9,'Portfolio Raw Data'!B:B,"Realized & Unrealized Performance Summary",'Portfolio Raw Data'!C:C,"Data",'Portfolio Raw Data'!D:D,"Total")+-1*SUMIFS('Portfolio Raw Data'!K:K,'Portfolio Raw Data'!A:A,A9,'Portfolio Raw Data'!B:B,"Realized & Unrealized Performance Summary",'Portfolio Raw Data'!C:C,"Data",'Portfolio Raw Data'!D:D,"Futures") -> 4026.1824 | J9: =SUMIFS('Portfolio Raw Data'!O:O,'Portfolio Raw Data'!A:A,A9,'Portfolio Raw Data'!B:B,"Change in Dividend Accruals",'Portfolio Raw Data'!C:C,"Data",'Portfolio Raw Data'!D:D,"Ending Dividend Accruals in USD") -> 69.9 | K9: =I9+H9+J9 -> 19667.825 | L9: =K9/B9 -> 0.035562936 | M9: {=PRODUCT(1+L$3:L9)-1} -> 0.48560726 | N9: =SUMIFS('Portfolio Raw Data'!P:P,'Portfolio Raw Data'!A:A,A9,'Portfolio Raw Data'!B:B,"Realized & Unrealized Performance Summary",'Portfolio Raw Data'!C:C,"Data",'Portfolio Raw Data'!D:D,"Futures") -> -2431 | O9: =SUMIFS('Portfolio Raw Data'!K:K,'Portfolio Raw Data'!A:A,A9,'Portfolio Raw Data'!B:B,"Realized & Unrealized Performance Summary",'Portfolio Raw Data'!C:C,"Data",'Portfolio Raw Data'!D:D,"Futures") -> 3597.25 | P9: =O9+N9 -> 1166.25 | Q9: =P9/B9 -> 0.0021087881 | R9: {=PRODUCT(1+Q$3:Q9)-1} -> -0.17922886 | S9: =P9+K9 -> 20834.075 | T9: =(B9+S9)/B9-1 -> 0.037671724 | U9: {=PRODUCT(1+T$3:T9)-1} -> 0.23756876 | V9: =VLOOKUP(A9,'SPY Raw Data'!A:E,5,0)/100 -> 0.012108974 | W9: {=PRODUCT(1+V$2:V9)-1} -> 0.16619421 | X9: =T9-V9 -> 0.02556275
A10: 2024-08 | B10: =B9+S9 -> 573876.84 | C10: =SUMIFS('Portfolio Raw Data'!M:M,'Portfolio Raw Data'!A:A,A10,'Portfolio Raw Data'!B:B,"Open Positions",'Portfolio Raw Data'!C:C,"Total",'Portfolio Raw Data'!E:E,"Stocks") -> 539556.92 | D10: =SUMIFS('Portfolio Raw Data'!M:M,'Portfolio Raw Data'!A:A,A10,'Portfolio Raw Data'!B:B,"Open Positions",'Portfolio Raw Data'!C:C,"Total",'Portfolio Raw Data'!E:E,"Futures") -> -366060 | F10: =SUMIFS('Portfolio Raw Data'!P:P,'Portfolio Raw Data'!A:A,A10,'Portfolio Raw Data'!B:B,"Realized & Unrealized Performance Summary",'Portfolio Raw Data'!C:C,"Data",'Portfolio Raw Data'!D:D,"Total (All Assets)") -> 22574.797 | G10: =SUMIFS('Portfolio Raw Data'!K:K,'Portfolio Raw Data'!A:A,A10,'Portfolio Raw Data'!B:B,"Realized & Unrealized Performance Summary",'Portfolio Raw Data'!C:C,"Data",'Portfolio Raw Data'!D:D,"Total (All Assets)") -> -16137.276 | H10: =SUMIFS('Portfolio Raw Data'!P:P,'Portfolio Raw Data'!A:A,A10,'Portfolio Raw Data'!B:B,"Realized & Unrealized Performance Summary",'Portfolio Raw Data'!C:C,"Data",'Portfolio Raw Data'!D:D,"Total")+-1*SUMIFS('Portfolio Raw Data'!P:P,'Portfolio Raw Data'!A:A,A10,'Portfolio Raw Data'!B:B,"Realized & Unrealized Performance Summary",'Portfolio Raw Data'!C:C,"Data",'Portfolio Raw Data'!D:D,"Futures") -> 28743.297 | I10: =SUMIFS('Portfolio Raw Data'!K:K,'Portfolio Raw Data'!A:A,A10,'Portfolio Raw Data'!B:B,"Realized & Unrealized Performance Summary",'Portfolio Raw Data'!C:C,"Data",'Portfolio Raw Data'!D:D,"Total")+-1*SUMIFS('Portfolio Raw Data'!K:K,'Portfolio Raw Data'!A:A,A10,'Portfolio Raw Data'!B:B,"Realized & Unrealized Performance Summary",'Portfolio Raw Data'!C:C,"Data",'Portfolio Raw Data'!D:D,"Futures") -> 22896.974 | J10: =SUMIFS('Portfolio Raw Data'!O:O,'Portfolio Raw Data'!A:A,A10,'Portfolio Raw Data'!B:B,"Change in Dividend Accruals",'Portfolio Raw Data'!C:C,"Data",'Portfolio Raw Data'!D:D,"Ending Dividend Accruals in USD") -> 50.6 | K10: =I10+H10+J10 -> 51690.871 | L10: =K10/B10 -> 0.090073109 | M10: {=PRODUCT(1+L$3:L10)-1} -> 0.61942052 | N10: =SUMIFS('Portfolio Raw Data'!P:P,'Portfolio Raw Data'!A:A,A10,'Portfolio Raw Data'!B:B,"Realized & Unrealized Performance Summary",'Portfolio Raw Data'!C:C,"Data",'Portfolio Raw Data'!D:D,"Futures") -> -6168.5 | O10: =SUMIFS('Portfolio Raw Data'!K:K,'Portfolio Raw Data'!A:A,A10,'Portfolio Raw Data'!B:B,"Realized & Unrealized Performance Summary",'Portfolio Raw Data'!C:C,"Data",'Portfolio Raw Data'!D:D,"Futures") -> -39034.25 | P10: =O10+N10 -> -45202.75 | Q10: =P10/B10 -> -0.078767336 | R10: {=PRODUCT(1+Q$3:Q10)-1} -> -0.24387881 | S10: =P10+K10 -> 6488.1211 | T10: =(B10+S10)/B10-1 -> 0.011305773 | U10: {=PRODUCT(1+T$3:T10)-1} -> 0.25156043 | V10: =VLOOKUP(A10,'SPY Raw Data'!A:E,5,0)/100 -> 0.023365671 | W10: {=PRODUCT(1+V$2:V10)-1} -> 0.19344312 | X10: =T10-V10 -> -0.012059899
A11: 2024-09 | B11: =B10+S10 -> 580364.96 | C11: =SUMIFS('Portfolio Raw Data'!M:M,'Portfolio Raw Data'!A:A,A11,'Portfolio Raw Data'!B:B,"Open Positions",'Portfolio Raw Data'!C:C,"Total",'Portfolio Raw Data'!E:E,"Stocks") -> 501385.9 | D11: =SUMIFS('Portfolio Raw Data'!M:M,'Portfolio Raw Data'!A:A,A11,'Portfolio Raw Data'!B:B,"Open Positions",'Portfolio Raw Data'!C:C,"Total",'Portfolio Raw Data'!E:E,"Futures") -> -382322.5 | F11: =SUMIFS('Portfolio Raw Data'!P:P,'Portfolio Raw Data'!A:A,A11,'Portfolio Raw Data'!B:B,"Realized & Unrealized Performance Summary",'Portfolio Raw Data'!C:C,"Data",'Portfolio Raw Data'!D:D,"Total (All Assets)") -> 37662.527 | G11: =SUMIFS('Portfolio Raw Data'!K:K,'Portfolio Raw Data'!A:A,A11,'Portfolio Raw Data'!B:B,"Realized & Unrealized Performance Summary",'Portfolio Raw Data'!C:C,"Data",'Portfolio Raw Data'!D:D,"Total (All Assets)") -> -12138.69 | H11: =SUMIFS('Portfolio Raw Data'!P:P,'Portfolio Raw Data'!A:A,A11,'Portfolio Raw Data'!B:B,"Realized & Unrealized Performance Summary",'Portfolio Raw Data'!C:C,"Data",'Portfolio Raw Data'!D:D,"Total")+-1*SUMIFS('Portfolio Raw Data'!P:P,'Portfolio Raw Data'!A:A,A11,'Portfolio Raw Data'!B:B,"Realized & Unrealized Performance Summary",'Portfolio Raw Data'!C:C,"Data",'Portfolio Raw Data'!D:D,"Futures") -> 41224.527 | I11: =SUMIFS('Portfolio Raw Data'!K:K,'Portfolio Raw Data'!A:A,A11,'Portfolio Raw Data'!B:B,"Realized & Unrealized Performance Summary",'Portfolio Raw Data'!C:C,"Data",'Portfolio Raw Data'!D:D,"Total")+-1*SUMIFS('Portfolio Raw Data'!K:K,'Portfolio Raw Data'!A:A,A11,'Portfolio Raw Data'!B:B,"Realized & Unrealized Performance Summary",'Portfolio Raw Data'!C:C,"Data",'Portfolio Raw Data'!D:D,"Futures") -> 226.06 | J11: =SUMIFS('Portfolio Raw Data'!O:O,'Portfolio Raw Data'!A:A,A11,'Portfolio Raw Data'!B:B,"Change in Dividend Accruals",'Portfolio Raw Data'!C:C,"Data",'Portfolio Raw Data'!D:D,"Ending Dividend Accruals in USD") -> 140.66 | K11: =I11+H11+J11 -> 41591.247 | L11: =K11/B11 -> 0.071663953 | M11: {=PRODUCT(1+L$3:L11)-1} -> 0.7354746 | N11: =SUMIFS('Portfolio Raw Data'!P:P,'Portfolio Raw Data'!A:A,A11,'Portfolio Raw Data'!B:B,"Realized & Unrealized Performance Summary",'Portfolio Raw Data'!C:C,"Data",'Portfolio Raw Data'!D:D,"Futures") -> -3562 | O11: =SUMIFS('Portfolio Raw Data'!K:K,'Portfolio Raw Data'!A:A,A11,'Portfolio Raw Data'!B:B,"Realized & Unrealized Performance Summary",'Portfolio Raw Data'!C:C,"Data",'Portfolio Raw Data'!D:D,"Futures") -> -12364.75 | P11: =O11+N11 -> -15926.75 | Q11: =P11/B11 -> -0.027442646 | R11: {=PRODUCT(1+Q$3:Q11)-1} -> -0.26462878 | S11: =P11+K11 -> 25664.497 | T11: =(B11+S11)/B11-1 -> 0.044221307 | U11: {=PRODUCT(1+T$3:T11)-1} -> 0.30690607 | V11: =VLOOKUP(A11,'SPY Raw Data'!A:E,5,0)/100 -> 0.02100375 | W11: {=PRODUCT(1+V$2:V11)-1} -> 0.2185099 | X11: =T11-V11 -> 0.023217557
A12: 2024-10 | B12: =B11+S11 -> 606029.46 | C12: =SUMIFS('Portfolio Raw Data'!M:M,'Portfolio Raw Data'!A:A,A12,'Portfolio Raw Data'!B:B,"Open Positions",'Portfolio Raw Data'!C:C,"Total",'Portfolio Raw Data'!E:E,"Stocks") -> 436128.83 | D12: =SUMIFS('Portfolio Raw Data'!M:M,'Portfolio Raw Data'!A:A,A12,'Portfolio Raw Data'!B:B,"Open Positions",'Portfolio Raw Data'!C:C,"Total",'Portfolio Raw Data'!E:E,"Futures") -> -160174 | F12: =SUMIFS('Portfolio Raw Data'!P:P,'Portfolio Raw Data'!A:A,A12,'Portfolio Raw Data'!B:B,"Realized & Unrealized Performance Summary",'Portfolio Raw Data'!C:C,"Data",'Portfolio Raw Data'!D:D,"Total (All Assets)") -> 18471.134 | G12: =SUMIFS('Portfolio Raw Data'!K:K,'Portfolio Raw Data'!A:A,A12,'Portfolio Raw Data'!B:B,"Realized & Unrealized Performance Summary",'Portfolio Raw Data'!C:C,"Data",'Portfolio Raw Data'!D:D,"Total (All Assets)") -> 14177.383 | H12: =SUMIFS('Portfolio Raw Data'!P:P,'Portfolio Raw Data'!A:A,A12,'Portfolio Raw Data'!B:B,"Realized & Unrealized Performance Summary",'Portfolio Raw Data'!C:C,"Data",'Portfolio Raw Data'!D:D,"Total")+-1*SUMIFS('Portfolio Raw Data'!P:P,'Portfolio Raw Data'!A:A,A12,'Portfolio Raw Data'!B:B,"Realized & Unrealized Performance Summary",'Portfolio Raw Data'!C:C,"Data",'Portfolio Raw Data'!D:D,"Futures") -> 14610.134 | I12: =SUMIFS('Portfolio Raw Data'!K:K,'Portfolio Raw Data'!A:A,A12,'Portfolio Raw Data'!B:B,"Realized & Unrealized Performance Summary",'Portfolio Raw Data'!C:C,"Data",'Portfolio Raw Data'!D:D,"Total")+-1*SUMIFS('Portfolio Raw Data'!K:K,'Portfolio Raw Data'!A:A,A12,'Portfolio Raw Data'!B:B,"Realized & Unrealized Performance Summary",'Portfolio Raw Data'!C:C,"Data",'Portfolio Raw Data'!D:D,"Futures") -> 20302.383 | J12: =SUMIFS('Portfolio Raw Data'!O:O,'Portfolio Raw Data'!A:A,A12,'Portfolio Raw Data'!B:B,"Change in Dividend Accruals",'Portfolio Raw Data'!C:C,"Data",'Portfolio Raw Data'!D:D,"Ending Dividend Accruals in USD") -> 45.3 | K12: =I12+H12+J12 -> 34957.817 | L12: =K12/B12 -> 0.057683363 | M12: {=PRODUCT(1+L$3:L12)-1} -> 0.83558261 | N12: =SUMIFS('Portfolio Raw Data'!P:P,'Portfolio Raw Data'!A:A,A12,'Portfolio Raw Data'!B:B,"Realized & Unrealized Performance Summary",'Portfolio Raw Data'!C:C,"Data",'Portfolio Raw Data'!D:D,"Futures") -> 3861 | O12: =SUMIFS('Portfolio Raw Data'!K:K,'Portfolio Raw Data'!A:A,A12,'Portfolio Raw Data'!B:B,"Realized & Unrealized Performance Summary",'Portfolio Raw Data'!C:C,"Data",'Portfolio Raw Data'!D:D,"Futures") -> -6125 | P12: =O12+N12 -> -2264 | Q12: =P12/B12 -> -0.003735792 | R12: {=PRODUCT(1+Q$3:Q12)-1} -> -0.26737597 | S12: =P12+K12 -> 32693.817 | T12: =(B12+S12)/B12-1 -> 0.053947571 | U12: {=PRODUCT(1+T$3:T12)-1} -> 0.37741048 | V12: =VLOOKUP(A12,'SPY Raw Data'!A:E,5,0)/100 -> -0.0089235917 | W12: {=PRODUCT(1+V$2:V12)-1} -> 0.20763641 | X12: =T12-V12 -> 0.062871163
A13: 2024-11 | B13: =B12+S12 -> 638723.28 | C13: =SUMIFS('Portfolio Raw Data'!M:M,'Portfolio Raw Data'!A:A,A13,'Portfolio Raw Data'!B:B,"Open Positions",'Portfolio Raw Data'!C:C,"Total",'Portfolio Raw Data'!E:E,"Stocks") -> 488304.8 | D13: =SUMIFS('Portfolio Raw Data'!M:M,'Portfolio Raw Data'!A:A,A13,'Portfolio Raw Data'!B:B,"Open Positions",'Portfolio Raw Data'!C:C,"Total",'Portfolio Raw Data'!E:E,"Futures") -> -125961 | F13: =SUMIFS('Portfolio Raw Data'!P:P,'Portfolio Raw Data'!A:A,A13,'Portfolio Raw Data'!B:B,"Realized & Unrealized Performance Summary",'Portfolio Raw Data'!C:C,"Data",'Portfolio Raw Data'!D:D,"Total (All Assets)") -> 31776.404 | G13: =SUMIFS('Portfolio Raw Data'!K:K,'Portfolio Raw Data'!A:A,A13,'Portfolio Raw Data'!B:B,"Realized & Unrealized Performance Summary",'Portfolio Raw Data'!C:C,"Data",'Portfolio Raw Data'!D:D,"Total (All Assets)") -> 6852.925 | H13: =SUMIFS('Portfolio Raw Data'!P:P,'Portfolio Raw Data'!A:A,A13,'Portfolio Raw Data'!B:B,"Realized & Unrealized Performance Summary",'Portfolio Raw Data'!C:C,"Data",'Portfolio Raw Data'!D:D,"Total")+-1*SUMIFS('Portfolio Raw Data'!P:P,'Portfolio Raw Data'!A:A,A13,'Portfolio Raw Data'!B:B,"Realized & Unrealized Performance Summary",'Portfolio Raw Data'!C:C,"Data",'Portfolio Raw Data'!D:D,"Futures") -> 34635.904 | I13: =SUMIFS('Portfolio Raw Data'!K:K,'Portfolio Raw Data'!A:A,A13,'Portfolio Raw Data'!B:B,"Realized & Unrealized Performance Summary",'Portfolio Raw Data'!C:C,"Data",'Portfolio Raw Data'!D:D,"Total")+-1*SUMIFS('Portfolio Raw Data'!K:K,'Portfolio Raw Data'!A:A,A13,'Portfolio Raw Data'!B:B,"Realized & Unrealized Performance Summary",'Portfolio Raw Data'!C:C,"Data",'Portfolio Raw Data'!D:D,"Futures") -> 4984.925 | J13: =SUMIFS('Portfolio Raw Data'!O:O,'Portfolio Raw Data'!A:A,A13,'Portfolio Raw Data'!B:B,"Change in Dividend Accruals",'Portfolio Raw Data'!C:C,"Data",'Portfolio Raw Data'!D:D,"Ending Dividend Accruals in USD") -> 39.73 | K13: =I13+H13+J13 -> 39660.559 | L13: =K13/B13 -> 0.062093492 | M13: {=PRODUCT(1+L$3:L13)-1} -> 0.94956034 | N13: =SUMIFS('Portfolio Raw Data'!P:P,'Portfolio Raw Data'!A:A,A13,'Portfolio Raw Data'!B:B,"Realized & Unrealized Performance Summary",'Portfolio Raw Data'!C:C,"Data",'Portfolio Raw Data'!D:D,"Futures") -> -2859.5 | O13: =SUMIFS('Portfolio Raw Data'!K:K,'Portfolio Raw Data'!A:A,A13,'Portfolio Raw Data'!B:B,"Realized & Unrealized Performance Summary",'Portfolio Raw Data'!C:C,"Data",'Portfolio Raw Data'!D:D,"Futures") -> 1868 | P13: =O13+N13 -> -991.5 | Q13: =P13/B13 -> -0.0015523154 | R13: {=PRODUCT(1+Q$3:Q13)-1} -> -0.26851324 | S13: =P13+K13 -> 38669.059 | T13: =(B13+S13)/B13-1 -> 0.060541177 | U13: {=PRODUCT(1+T$3:T13)-1} -> 0.46080053 | V13: =VLOOKUP(A13,'SPY Raw Data'!A:E,5,0)/100 -> 0.0596 | W13: {=PRODUCT(1+V$2:V13)-1} -> 0.27961154 | X13: =T13-V13 -> 0.00094117679
A14: 2024-12 | B14: =B13+S13 -> 677392.34 | C14: =SUMIFS('Portfolio Raw Data'!M:M,'Portfolio Raw Data'!A:A,A14,'Portfolio Raw Data'!B:B,"Open Positions",'Portfolio Raw Data'!C:C,"Total",'Portfolio Raw Data'!E:E,"Stocks") -> 501794.27 | D14: =SUMIFS('Portfolio Raw Data'!M:M,'Portfolio Raw Data'!A:A,A14,'Portfolio Raw Data'!B:B,"Open Positions",'Portfolio Raw Data'!C:C,"Total",'Portfolio Raw Data'!E:E,"Futures") -> -101810.5 | F14: =SUMIFS('Portfolio Raw Data'!P:P,'Portfolio Raw Data'!A:A,A14,'Portfolio Raw Data'!B:B,"Realized & Unrealized Performance Summary",'Portfolio Raw Data'!C:C,"Data",'Portfolio Raw Data'!D:D,"Total (All Assets)") -> 20921.269 | G14: =SUMIFS('Portfolio Raw Data'!K:K,'Portfolio Raw Data'!A:A,A14,'Portfolio Raw Data'!B:B,"Realized & Unrealized Performance Summary",'Portfolio Raw Data'!C:C,"Data",'Portfolio Raw Data'!D:D,"Total (All Assets)") -> -7266.675 | H14: =SUMIFS('Portfolio Raw Data'!P:P,'Portfolio Raw Data'!A:A,A14,'Portfolio Raw Data'!B:B,"Realized & Unrealized Performance Summary",'Portfolio Raw Data'!C:C,"Data",'Portfolio Raw Data'!D:D,"Total")+-1*SUMIFS('Portfolio Raw Data'!P:P,'Portfolio Raw Data'!A:A,A14,'Portfolio Raw Data'!B:B,"Realized & Unrealized Performance Summary",'Portfolio Raw Data'!C:C,"Data",'Portfolio Raw Data'!D:D,"Futures") -> 17800.769 | I14: =SUMIFS('Portfolio Raw Data'!K:K,'Portfolio Raw Data'!A:A,A14,'Portfolio Raw Data'!B:B,"Realized & Unrealized Performance Summary",'Portfolio Raw Data'!C:C,"Data",'Portfolio Raw Data'!D:D,"Total")+-1*SUMIFS('Portfolio Raw Data'!K:K,'Portfolio Raw Data'!A:A,A14,'Portfolio Raw Data'!B:B,"Realized & Unrealized Performance Summary",'Portfolio Raw Data'!C:C,"Data",'Portfolio Raw Data'!D:D,"Futures") -> -553.175 | J14: =SUMIFS('Portfolio Raw Data'!O:O,'Portfolio Raw Data'!A:A,A14,'Portfolio Raw Data'!B:B,"Change in Dividend Accruals",'Portfolio Raw Data'!C:C,"Data",'Portfolio Raw Data'!D:D,"Ending Dividend Accruals in USD") -> 123.79 | K14: =I14+H14+J14 -> 17371.384 | L14: =K14/B14 -> 0.025644494 | M14: {=PRODUCT(1+L$3:L14)-1} -> 0.99955583 | N14: =SUMIFS('Portfolio Raw Data'!P:P,'Portfolio Raw Data'!A:A,A14,'Portfolio Raw Data'!B:B,"Realized & Unrealized Performance Summary",'Portfolio Raw Data'!C:C,"Data",'Portfolio Raw Data'!D:D,"Futures") -> 3120.5 | O14: =SUMIFS('Portfolio Raw Data'!K:K,'Portfolio Raw Data'!A:A,A14,'Portfolio Raw Data'!B:B,"Realized & Unrealized Performance Summary",'Portfolio Raw Data'!C:C,"Data",'Portfolio Raw Data'!D:D,"Futures") -> -6713.5 | P14: =O14+N14 -> -3593 | Q14: =P14/B14 -> -0.0053041639 | R14: {=PRODUCT(1+Q$3:Q14)-1} -> -0.27239316 | S14: =P14+K14 -> 13778.384 | T14: =(B14+S14)/B14-1 -> 0.02034033 | U14: {=PRODUCT(1+T$3:T14)-1} -> 0.4905137 | V14: =VLOOKUP(A14,'SPY Raw Data'!A:E,5,0)/100 -> -0.0241 | W14: {=PRODUCT(1+V$2:V14)-1} -> 0.24877291 | X14: =T14-V14 -> 0.04444033
A17: Fund Deposit
A18: 45413 | B18: =-1*B7 -> -282032.4
A19: 45422 | B19: =-1*E7 -> -250000
A20: 45443 | B20: =B7+E7+S7 -> 542448.15
A21: Yearly return | B21: =XIRR(B18:B20,A18:A20,0.25) -> 0.31589603
A22: Monthly return | B22: =(1+B21)^(1/12)-1 -> 0.023140159

Sheet Portfolio Raw Data
A1: 2 | B1: 3 | C1: 4 | D1: 5 | E1: 6 | F1: 7 | G1: 8 | H1: 9 | I1: 10 | J1: 11 | K1: 12 | L1: 13 | M1: 14 | N1: 15 | O1: 16 | P1: 17 | Q1: 18 | R1: 19 | S1: 20
A2: Month | B2: Statement | C2: Header | D2: Field Name | E2: Field Value
A3: 2024-01 | B3: Statement | C3: Data | D3: BrokerName | E3: Interactive Brokers LLC
A4: 2024-01 | B4: Statement | C4: Data | D4: BrokerAddress
A5: 2024-01 | B5: Statement | C5: Data | D5: Title | E5: Activity Statement
A6: 2024-01 | B6: Statement | C6: Data | D6: Period | E6: January 1, 2024 - January 31, 2024
A7: 2024-01 | B7: Statement | C7: Data | D7: WhenGenerated | E7: 2024-09-02, 08:20:02 EDT
A8: 2024-01 | B8: Account Information | C8: Header | D8: Field Name | E8: Field Value
A9: 2024-01 | B9: Account Information | C9: Data | D9: Name
A10: 2024-01 | B10: Account Information | C10: Data | D10: Account
A11: 2024-01 | B11: Account Information | C11: Data | D11: Investment Advisor
A12: 2024-01 | B12: Account Information | C12: Data | D12: Account Type
A13: 2024-01 | B13: Account Information | C13: Data | D13: Customer Type | E13: Individual
A14: 2024-01 | B14: Account Information | C14: Data | D14: Account Capabilities | E14: Margin
A15: 2024-01 | B15: Account Information | C15: Data | D15: Base Currency | E15: USD
A16: 2024-01 | B16: Net Asset Value | C16: Header | D16: Asset Class | E16: Prior Total | F16: Current Long | G16: Current Short | H16: Current Total | I16: Change
A17: 2024-01 | B17: Net Asset Value | C17: Data | D17: Cash | E17: 250000 | F17: 68923.413 | G17: 0 | H17: 68923.413 | I17: -181076.59
A18: 2024-01 | B18: Net Asset Value | C18: Data | D18: Stock | E18: 0 | F18: 186063.87 | G18: 0 | H18: 186063.87 | I18: 186063.87
A19: 2024-01 | B19: Net Asset Value | C19: Data | D19: Interest Accruals | E19: 96.6 | F19: 285.92 | G19: 0 | H19: 285.92 | I19: 189.32
A20: 2024-01 | B20: Net Asset Value | C20: Data | D20: Dividend Accruals | E20: 0 | F20: 57.17 | G20: 0 | H20: 57.17 | I20: 57.17
A21: 2024-01 | B21: Net Asset Value | C21: Data | D21: Total | E21: 250096.6 | F21: 255330.37 | G21: 0 | H21: 255330.37 | I21: 5233.773
A22: 2024-01 | B22: Net Asset Value | C22: Header | D22: Time Weighted Rate of Return
A23: 2024-01 | B23: Net Asset Value | C23: Data | D23: 0.020927006
A24: 2024-01 | B24: Change in NAV | C24: Header | D24: Field Name | E24: Field Value
A25: 2024-01 | B25: Change in NAV | C25: Data | D25: Starting Value | E25: 250096.6
A26: 2024-01 | B26: Change in NAV | C26: Data | D26: Mark-to-Market | E26: 4920.99
A27: 2024-01 | B27: Change in NAV | C27: Data | D27: Dividends | E27: 29.9
A28: 2024-01 | B28: Change in NAV | C28: Data | D28: Withholding Tax | E28: -66.93
A29: 2024-01 | B29: Change in NAV | C29: Data | D29: Change in Dividend Accruals | E29: 57.17
A30: 2024-01 | B30: Change in NAV | C30: Data | D30: Interest | E30: 193.2
A31: 2024-01 | B31: Change in NAV | C31: Data | D31: Change in Interest Accruals | E31: 189.32
A32: 2024-01 | B32: Change in NAV | C32: Data | D32: Advisor Fees | E32: -9.66
A33: 2024-01 | B33: Change in NAV | C33: Data | D33: Commissions | E33: -80.217
A34: 2024-01 | B34: Change in NAV | C34: Data | D34: Ending Value | E34: 255330.37
A35: 2024-01 | B35: Mark-to-Market Performance Summary | C35: Header | D35: Asset Category | E35: Symbol | F35: Prior Quantity | G35: Current Quantity | H35: Prior Price | I35: Current Price | J35: Mark-to-Market P/L Position | K35: Mark-to-Market P/L Transaction | L35: Mark-to-Market P/L Commissions | M35: Mark-to-Market P/L Other | N35: Mark-to-Market P/L Total | O35: Code
A36: 2024-01 | B36: Mark-to-Market Performance Summary | C36: Data | D36: Stocks | E36: AAPL | F36: 0 | G36: 36 | H36: -- | I36: 184.4 | J36: 365.49 | K36: 8.55 | L36: -2.6 | M36: 0 | N36: 371.44
A37: 2024-01 | B37: Mark-to-Market Performance Summary | C37: Data | D37: Stocks | E37: AMT | F37: 0 | G37: 12 | H37: -- | I37: 195.65 | J37: -237.72 | K37: 20.04 | L37: -1.3 | M37: 0 | N37: -218.98
A38: 2024-01 | B38: Mark-to-Market Performance Summary | C38: Data | D38: Stocks | E38: AMZN | F38: 0 | G38: 104 | H38: -- | I38: 155.2 | J38: 1105.52 | K38: -70.72 | L38: -1.3 | M38: 0 | N38: 1033.5
A39: 2024-01 | B39: Mark-to-Market Performance Summary | C39: Data | D39: Stocks | E39: ANET | F39: 0 | G39: 31 | H39: -- | I39: 258.68 | J39: 907.68 | K39: 11.78 | L39: -1.3 | M39: 0 | N39: 918.16
A40: 2024-01 | B40: Mark-to-Market Performance Summary | C40: Data | D40: Stocks | E40: AVGO | F40: 0 | G40: 7 | H40: -- | I40: 1180 | J40: 916.93 | K40: -66.01 | L40: -1.3 | M40: 0 | N40: 849.62
...

Sheet SPY Raw Data
A1: Month Identifier | B1: Dates for report | C1: adj_close_price | D1: start-of-month value for each date | E1: Cumulative Monthly % Change:
A2: 2023-12 | B2: 45289 | C2: 470.8702 | D2: 470.8702 | E2: 0
A3: 2024-01 | B3: 45322 | C3: 478.3695 | D3: 470.8702 | E3: 1.592647
A4: 2024-02 | B4: 45351 | C4: 503.3341 | D4: 478.3695 | E4: 5.2186856
A5: 2024-03 | B5: 45379 | C5: 519.794 | D5: 503.3341 | E5: 3.2701738
A6: 2024-04 | B6: 45412 | C6: 498.8361 | D6: 519.794 | E6: -4.0319627
A7: 2024-05 | B7: 45443 | C7: 524.0671 | D7: 498.8361 | E7: 5.057974
A8: 2024-06 | B8: 45471 | C8: 542.5563 | D8: 524.0671 | E8: 3.5280215
A9: 2024-07 | B9: 45504 | C9: 549.1261 | D9: 542.5563 | E9: 1.2108974
A10: 2024-08 | B10: 45534 | C10: 561.9568 | D10: 549.1261 | E10: 2.3365671
A11: 2024-09 | B11: 45565 | C11: 573.76 | D11: 561.9568 | E11: 2.100375
A12: 2024-10 | B12: 45596 | C12: 568.64 | D12: 573.76 | E12: -0.89235917
A13: 2024-11 | B13: 45625 | C13: 600.5293 | D13: 566.733 | E13: 5.96
... A15: 2025-01 | B15: 45685 | C15: 604.52 | D15: 586.08 | E15: 3.15
